# ‚õî Erros Customizados

O erro n√£o √© nada mais que um objeto comum no javascript.

Ele vem nos ajudar quando h√° problemas, indicando o que precisa ser resolvido para tudo normalizar.

O **caminho de exce√ß√£o** deve ser um dos pilares em qualquer projeto, pois trabalhamos sempre em 2 caminhos:

- **O caminho feliz:** onde tudo flui como esperado.
- **E o caminho triste (haha):** onde acontece algo inesperado, desviando o fluxo padr√£o.

```js
// criado arquivo tempor√°rio teste.js na raiz
// s√≥ pra for√ßar o fluxo de exce√ß√£o
console.log("Essa linha executou?");

// pega o exit code no terminal
echo $? // saida: 0 - saiu com sucesso
```

Agora criando um m√©todo que nao existe pra for√ßar o erro.

```js
console.log("Essa linha executou?");
user.save(); // n√£o existe
```

```bash
# log terminal
# executa o console log, mas depois entra no erro
‚ùØ node teste.js
Essa linha executou?
/home/thiago/git/clone-tabnews/teste.js:2
user.save();
^

ReferenceError: user is not defined
    at Object.<anonymous> (/home/thiago/git/clone-tabnews/teste.js:2:1)
    at Module._compile (node:internal/modules/cjs/loader:1364:14)
    at Module._extensions..js (node:internal/modules/cjs/loader:1422:10)
    at Module.load (node:internal/modules/cjs/loader:1203:32)
    at Module._load (node:internal/modules/cjs/loader:1019:12)
    at Function.executeUserEntryPoint [as runMain] (node:internal/modules/run_main:128:12)
    at node:internal/main/run_main_module:28:49

Node.js v18.20.8
```

Agora, se inverter o `console.log` com `user.save()`, √© apenas gerado erro e a execu√ß√£o n√£o continua, nem mostra mais o resultado do console.log

## Entendendo a mec√¢nica

Existem duas mec√¢nicas principais que lidam com exce√ß√µes.

A primeira √© o lan√ßamento do erro, exibindo as informa√ß√µes do que aconteceu no fluxo do processo.

E a segunda √© o empilhamento do erro, passando por todas as camadas e abstra√ß√µes nos scripts esperando ser capturada. Caso n√£o haja a captura e tratamento, o processo √© encerrado.

**Resumindo de forma t√©cnica:**

Existem duas mec√¢nicas principais no tratamento de exce√ß√µes:

Lan√ßamento (throw):
Quando algo inesperado ocorre, uma exce√ß√£o √© lan√ßada. Esse lan√ßamento cont√©m informa√ß√µes √∫teis, como a mensagem de erro, tipo da exce√ß√£o e, em alguns casos, a stack trace. Isso serve para indicar que o fluxo normal foi interrompido por um problema.

Propaga√ß√£o (empilhamento):
Ap√≥s o lan√ßamento, a exce√ß√£o sobe (propaga) pela pilha de chamadas, passando por todas as camadas e abstra√ß√µes do c√≥digo. Esse empilhamento continua at√© que a exce√ß√£o seja capturada (try/catch). Se n√£o houver captura em nenhuma camada, a aplica√ß√£o √© encerrada com erro.

Esse modelo permite separar responsabilidade: camadas inferiores apenas lan√ßam o erro, enquanto camadas superiores decidem como lidar (exibir mensagem, registrar log, encerrar, etc.).

### Lan√ßando com throw

Vamos lan√ßar uma exce√ß√£o.

```js
throw true;
console.log("Essa linha executou?");
```

```bash
# sa√≠da na console
‚ùØ node teste.js

/home/thiago/git/clone-tabnews/teste.js:1
throw true;
^
true
(Use `node --trace-uncaught ...` to show where the exception was thrown)

Node.js v18.20.8

# c√≥digo de sa√≠da 1 - erro gen√©rico
‚ùØ echo $?
1
```

### Lan√ßando e tratando com try catch

Agora vamos capturar esse erro gen√©rico com um bloco **try/catch**.

```js
// o c√≥digo dentro do bloco try √© avaliado.
// dentro do bloco de c√≥digo catch, vem o c√≥digo para tratar o erro avaliado pelo try.
try {
  throw true;
  console.log("Essa linha executou?");
} catch (error) {
  console.log(error);
}

// sa√≠da terminal
‚ùØ node teste.js
true
```

Explica√ß√£o:

O **bloco try** executa seu conte√∫do at√© que algo cause um erro (neste caso, throw true).

O **throw** interrompe imediatamente a execu√ß√£o do **bloco try** e transfere o controle para o catch.

O valor passado no **throw** (neste caso, **true**) √© **injetado no par√¢metro error** do catch.

A linha console.log("Essa linha executou?") nunca ser√° executada, pois est√° **ap√≥s o throw**.

O catch apenas **imprime o valor capturado**, que foi lan√ßado no throw.

O c√≥digo de sa√≠da na console √© 0, indicando um fluxo padr√£o para encerramento.

> Usando console.log(typeof error), obtemos o tipo do erro, no caso do true, boolean

```js
// testando string
try {
  throw "teste de string";
  console.log("Essa linha executou?");
} catch (error) {
  console.log(error);
  console.log(typeof error);
}

// sa√≠da
‚ùØ node teste.js
teste de string
string

// testando o lan√ßamento de um objeto
try {
  throw {
    mensagem: "Mensagem de erro",
    motivo: "Faltou o par√¢metro X",
  };
  console.log("Essa linha executou?");
} catch (error) {
  console.log(error);
  console.log(typeof error);
}

// sa√≠da
‚ùØ node teste.js
{ mensagem: 'Mensagem de erro', motivo: 'Faltou o par√¢metro X' }
object
```

### Fun√ß√£o construtora no javascript Error

Como o throw n√£o est√° relacionado diretamente a erros, o javascript possui uma fun√ß√£o especifica para erros.

```js
// declara√ß√£o
new Error();

// testando
try {
  const error = new Error();
  console.log(error);
} catch (error) {
  console.log(error);
  console.log(typeof error);
}

// sa√≠da. Essa propriedade especial exibe a toda pilha de erro (stack)
‚ùØ node teste.js
Error
    at Object.<anonymous> (/home/thiago/git/clone-tabnews/teste.js:2:17)
    at Module._compile (node:internal/modules/cjs/loader:1364:14)
    at Module._extensions..js (node:internal/modules/cjs/loader:1422:10)
    at Module.load (node:internal/modules/cjs/loader:1203:32)
    at Module._load (node:internal/modules/cjs/loader:1019:12)
    at Function.executeUserEntryPoint [as runMain] (node:internal/modules/run_main:128:12)
    at node:internal/main/run_main_module:28:49
```

Analisando a mensagem de erro, a primeira sempre √© o mais pr√≥ximo de onde o erro foi gerado.

## Padronizando a captura de erros

Iniciando com um exemplo simples, j√° que qualquer coisa no try ser√° capturada.

```js
function salvarUsuario(input) {
  // se n√£o informar a entrada, lan√ßa o erro
  if (!input) {
    throw "error-input-undefined";
  }
}

try {
  // como n√£o foi informado o input, vai lan√ßar a string de erro
  salvarUsuario();
} catch (error) {
  console.log(typeof error.stack);
  console.log(typeof error);
}

// sa√≠da
‚ùØ node teste.js
undefined // n√£o temos nada na stack, dificil analisar
string
```

Comparando exatamente na captura o erro lan√ßado para exibir na console

```js
function salvarUsuario(input) {
  if (!input) {
    throw "error-input-undefined";
  }
}

try {
  salvarUsuario();
} catch (error) {
  if (error === "error-input-undefined") {
    console.log("√â necess√°rio enviar um 'input'.");
  }
}

// sa√≠da
‚ùØ node teste.js
√â necess√°rio enviar um 'input'.
```

> Se no salvarUsuario for enviado um objeto vazio, passa sem problemas na captura. Isso √© um problema.

Comparando se o objeto enviado possui a propriedade name

```js
function salvarUsuario(input) {
  if (!input) {
    throw "error-input-undefined";
  }

  if (!input.name) {
    throw "error-name-undefined";
  }
}

try {
  salvarUsuario({});
} catch (error) {
  if (error === "error-input-undefined") {
    console.log("√â necess√°rio enviar um 'input'.");
  }

  if (error === "error-name-undefined") {
    console.log("√â necess√°rio enviar o 'name'.");
  }
}

// sa√≠da
‚ùØ node teste.js
√â necess√°rio enviar o 'name'.
```

Legal temos o problema, mas n√£o temos a stack para indicar a origem do problema com essa abordagem.

```js
if (error === "error-name-undefined") {
  console.log("√â necess√°rio enviar o 'name'.");
  console.log(error.stack); // s√≥ retorna undefined, n√£o ajudando em nada
}
```

Pra resolver isso,o objeto **Error** do javascript que compartilha todos os pontos de lan√ßamento de erro, detalhando onde est√£o sendo capturados os erros no c√≥digo.

```js
function salvarUsuario(input) {
  if (!input) {
    // lan√ßa um novo objeto Error. O construtor dele aceita uma string como par√¢metro
    throw new Error("error-input-undefined");
  }

  if (!input.name) {
    throw new Error("error-name-undefined");
  }
}

try {
  salvarUsuario({});
} catch (error) {
  // pra comparar a string, acessamos a propriedade message do objeto Error
  if (error.message === "error-input-undefined") {
    console.log("√â necess√°rio enviar um 'input'.");
    console.log(error.stack);
  }

  if (error.message === "error-name-undefined") {
    console.log("√â necess√°rio enviar o 'name'.");
    console.log(error.stack);
  }
}

// agora sim, na sa√≠da temos a stack
‚ùØ node teste.js
√â necess√°rio enviar o 'name'.
Error: error-name-undefined
    at salvarUsuario (/home/thiago/git/clone-tabnews/teste.js:7:11) // linha 7, coluna 11 (qtd caracteres)
    at Object.<anonymous> (/home/thiago/git/clone-tabnews/teste.js:12:3) // linha 12, coluna 3
    // ...
```

> üí° O VS Code mostra no rodap√© qual linha e coluna est√° o cursor

Agora uma falha grave!

```js
function salvarUsuario(input) {
  if (!input) {
    throw new Error("error-input-undefined");
  }

  if (!input.name) {
    throw new Error("error-name-undefined");
  }

  // esse m√©todo n√£o existe
  user.save(input);
}

try {
  // propriedade name preenchida
  salvarUsuario({
    name: "Thiago Carvalho",
  });
} catch (error) {
  if (error.message === "error-input-undefined") {
    console.log("√â necess√°rio enviar um 'input'.");
    console.log(error.stack);
  }

  if (error.message === "error-name-undefined") {
    console.log("√â necess√°rio enviar o 'name'.");
    console.log(error.stack);
  }
}

// n√£o saiu nada na console
‚ùØ node teste.js
```

Temos ai um **erro engolido** pelo catch, ficando invis√≠vel no sistema! Em produ√ß√£o, caos j√° estaria instalado por completo.

Pra resolver isso, podemos colocar uma condi√ß√£o gen√©rica, fazendo o `runtime do javascript` pegar qualquer erro n√£o tratado por √∫ltimo no catch.

```js
catch (error) {
  if (error.message === "error-input-undefined") {
    console.log("√â necess√°rio enviar um 'input'.");
    console.log(error.stack);
  }

  if (error.message === "error-name-undefined") {
    console.log("√â necess√°rio enviar o 'name'.");
    console.log(error.stack);
  }

  // caso n√£o tenha sido pego no tratamento espec√≠fico, entra aqui
  console.log("Erro desconhecido");
  console.log(error.stack);
}

// sa√≠da
‚ùØ node teste.js
Erro desconhecido
ReferenceError: user is not defined // o m√©todo user √© indefinido, pois n√£o existe no c√≥digo
    at salvarUsuario (/home/thiago/git/clone-tabnews/teste.js:10:3)
    at Object.<anonymous> (/home/thiago/git/clone-tabnews/teste.js:14:3)
```

### Melhorando os padr√µes com Custom Errors

O tratamento est√° ficando mais profissional, mas √© preciso centralizar o lan√ßamento de erros e criar formas para evitar centenas de **IFs** repetitivos que validam apenas strings. Vou continuar em outro documento espec√≠fico, esse t√° gigante. üòÉ
